<?xml version = "1.0"?>
<robot xmlns:xacro = "http://www.ros.org/wiki/xacro" name = "my_little_robot">
	<xacro:property name = "wheel_thickness" value = "0.25">
	<xacro:property name = "wheel_radius" value = "1">


	<!--Materials-->
	<material name = "green">
		<color rgba = "0 0.8 0 1"/>
	</material>
	
	<material name = "blue">
		<color rgba = "0 0 0.8 1"/>
	</material>
	
	<!--Links-->
	<link name = "base_link">
		<visual>
			<geometry>
				<box size ="2 1 0.5"/>
			</geometry>
			<material name = "green"/>
		</visual>
		<collision>
			<geometry>
				<box size ="2 1 0.5"/>
			</geometry>
		</collision>
		<inertial>
			<mass value = "1"/>
			<inertia ixx = "0.354" ixy = "0.0" ixz = "0.0" iyz = "0.0" iyy = "0.104" izz = "0.416"/>
		</inertial>
	</link>

	<link name = "front_left_wheel">
		<visual>
			<geometry>
				<cylinder length = "${wheel_thickness}" radius = "${wheel_radius}"/>
			</geometry>
			<origin rpy = "-1.57 0 0" xyz = "0 0 0"/>
			<material name = "blue"/>
		</visual>
		<collision>
			<geometry>
				<cylinder length = "0.25" radius = "0.3"/>
			</geometry>
		</collision>
		<inertial>
			<mass value = "0.25"/>
			<inertia ixx = "0.007" ixy = "0.0" ixz = "0.0" iyz = "0.0" iyy = "0.0" izz = "0.007"/>
		</inertial>
	</link>
	
	<link name = "front_right_wheel">
		<visual>
			<geometry>
				<cylinder length = "0.25" radius = "0.3"/>
			</geometry>
			<origin rpy = "1.57 0 0" xyz = "0 0 0"/>
			<material name = "blue"/>
		</visual>
		<collision>
			<geometry>
				<cylinder length = "0.25" radius = "0.3"/>
			</geometry>
		</collision>
		<inertial>
			<mass value = "0.25"/>
			<inertia ixx = "0.007" ixy = "0.0" ixz = "0.0" iyz = "0.0" iyy = "0.0" izz = "0.007"/>
		</inertial>
	</link>
	
	<link name = "rear_left_wheel">
		<visual>
			<geometry>
				<cylinder length = "0.25" radius = "0.3"/>
			</geometry>
			<origin rpy = "-1.57 0 0" xyz = "0 0 0"/>
			<material name = "blue"/>
		</visual>
		<collision>
			<geometry>
				<cylinder length = "0.25" radius = "0.3"/>
			</geometry>
		</collision>
		<inertial>
			<mass value = "0.25"/>
			<inertia ixx = "0.007" ixy = "0.0" ixz = "0.0" iyz = "0.0" iyy = "0.0" izz = "0.007"/>
		</inertial>
	</link>
	
	<link name = "rear_right_wheel">
		<visual>
			<geometry>
				<cylinder length = "0.25" radius = "0.3"/>
			</geometry>
			<origin rpy = "1.57 0 0" xyz = "0 0 0" />
			<material name = "blue"/>
		</visual>
		<collision>
			<geometry>
				<cylinder length = "0.25" radius = "0.3"/>
			</geometry>
		</collision>
		<inertial>
			<mass value = "0.25"/>
			<inertia ixx = "0.007" ixy = "0.0" ixz = "0.0" iyz = "0.0" iyy = "0.0" izz = "0.007"/>
		</inertial>
	</link>

	<!--Joints-->
	<joint name = "base_to_front_left_wheel" type = "continuous">
		<parent link = "base_link"/>
		<child link = "front_left_wheel"/>
		<axis xyz = "0 1 0"/>
		<origin xyz ="0.5 0.625 0"/>
	</joint>

	<joint name = "base_to_front_right_wheel" type = "continuous">
		<parent link = "base_link"/>
		<child link = "front_right_wheel"/>
		<axis xyz = "0 -1 0"/>
		<origin  xyz = "0.5 -0.625 0"/>
	</joint>

	<joint name = "base_to_rear_left_wheel" type = "continuous">
		<parent link = "base_link"/>
		<child link = "rear_left_wheel"/>
		<axis xyz = "0 1 0"/>
		<origin xyz = "-0.5 0.625 0"/>
	</joint>

	<joint name = "base_to_rear_right_wheel" type = "continuous">
		<parent link = "base_link"/>
		<child link = "rear_right_wheel"/>
		<axis xyz = "0 -1 0"/>
		<origin xyz = "-0.5 -0.625 0"/>
	</joint>
</robot>
